#VRML_SIM R2022a utf8
WorldInfo {
  basicTimeStep 64
  contactProperties [
    ContactProperties {
      material2 "dumbell"
    }
  ]
}
Viewpoint {
  orientation -0.12674118036548163 0.02561510976676398 0.9916050319311622 3.119587709249714
  position 0.7003369436954764 -0.06777002087891836 0.32210146759501684
}
TexturedBackground {
}
TexturedBackgroundLight {
}
SpotLight {
  attenuation 0 0 1
  beamWidth 1
  cutOffAngle 1.5
  direction 0 1 -1
  intensity 4
  location 1 1 1
}
PointLight {
  attenuation 0 0 1
  location 0 0.3 0
  on FALSE
}
DirectionalLight {
  direction 0 -1 0
  on FALSE
}
Floor {
  size 1 1
}
Solid {
  translation -0.55051 0.0534917 0.0492359
  rotation 3.0508606576118467e-16 -3.737747270231572e-16 1 1.55116
  children [
    Shape {
      appearance PBRAppearance {
        baseColor 0 0 1
        roughness 0.5
        metalness 0
      }
      geometry DEF WALL_GEOMETRY Box {
        size 1.1 0.1 0.1
      }
    }
  ]
  name "solid(1)"
  boundingObject Box {
    size 0.1 0.1 0.1
  }
  physics Physics {
  }
}
Solid {
  translation 0.47893581914675315 0.045169804541256485 0.04923174321317286
  rotation 2.4298141955859254e-11 4.07808276722021e-11 1 1.5511319456926784
  children [
    Shape {
      appearance PBRAppearance {
        baseColor 0 0 1
        roughness 1
        metalness 0
      }
      geometry DEF WALL_GEOMETRY Box {
        size 1.1 0.1 0.1
      }
    }
  ]
  name "solid(3)"
  boundingObject Box {
    size 0.1 0.1 0.1
  }
  physics Physics {
  }
}
Solid {
  translation -0.042481103056426626 -0.4666455343989886 0.04923585892309267
  rotation -4.0697853783738257e-13 -9.764130670339126e-12 1 -3.1285072091601687
  children [
    Shape {
      appearance PBRAppearance {
        baseColor 0 0 1
        roughness 1
        metalness 0
      }
      geometry DEF WALL_GEOMETRY Box {
        size 1.1 0.1 0.1
      }
    }
  ]
  name "solid(4)"
  boundingObject Box {
    size 0.1 0.1 0.1
  }
  physics Physics {
  }
}
Solid {
  translation -0.0557624016216142 0.5326270003413278 0.04923585892427949
  rotation 1.6434349606997356e-10 8.207279009788018e-10 -1 0.01963489999999961
  children [
    Shape {
      appearance PBRAppearance {
        baseColor 0 0 1
        roughness 1
        metalness 0
      }
      geometry DEF WALL_GEOMETRY Box {
        size 1.1 0.1 0.1
      }
    }
  ]
  name "solid(2)"
  boundingObject Box {
    size 0.1 0.1 0.1
  }
  physics Physics {
  }
}
Robot {
  translation -0.00543624 0.0282559 0.1
  children [
    DistanceSensor {
      translation 0.1 0.02 0
      rotation 0 0 1 -1.27
      children [
        DEF Sensor Shape {
          appearance PBRAppearance {
            baseColor 0 0 1
            roughness 1
            metalness 0
          }
          geometry Box {
            size 0.01 0.01 0.01
          }
        }
      ]
      name "ds_left"
      boundingObject USE Sensor
      physics Physics {
      }
    }
    DistanceSensor {
      translation 0.1 -0.02 0
      rotation 0 0 1 -1.87
      children [
        DEF Sensor Shape {
          appearance PBRAppearance {
            baseColor 0 0 1
            roughness 1
            metalness 0
          }
          geometry Box {
            size 0.01 0.01 0.01
          }
        }
      ]
      name "ds_right"
      boundingObject USE Sensor
      physics Physics {
      }
    }
    HingeJoint {
      jointParameters HingeJointParameters {
        axis 0 1 0
        anchor 0.05 0.06 0
      }
      device [
        RotationalMotor {
          name "wheel1"
        }
      ]
      endPoint Solid {
        translation 0.05 0.06 0
        rotation 1 0 0 1.5708
        children [
          Shape {
            appearance PBRAppearance {
              baseColor 0 1 0
              roughness 1
              metalness 0
            }
            geometry DEF Wheel_Geometry Cylinder {
              height 0.02
              radius 0.04
            }
          }
        ]
        boundingObject USE Wheel_Geometry
        physics Physics {
        }
      }
    }
    HingeJoint {
      jointParameters HingeJointParameters {
        axis 0 1 0
        anchor 0.05 -0.06 1.22354e-07
      }
      device [
        RotationalMotor {
          name "wheel2"
        }
      ]
      endPoint Solid {
        translation 0.05 -0.06 1.22354e-07
        rotation 0.9999999999999998 -9.589759999999996e-09 -9.589789999999996e-09 1.5707953071795862
        children [
          Shape {
            appearance PBRAppearance {
              baseColor 0 1 0
              roughness 1
              metalness 0
            }
            geometry Cylinder {
              height 0.02
              radius 0.04
            }
          }
        ]
        name "solid(1)"
        boundingObject USE Wheel_Geometry
        physics Physics {
        }
      }
    }
    HingeJoint {
      jointParameters HingeJointParameters {
        axis 0 1 0
        anchor -0.05 0.06 4.68944e-14
      }
      device [
        RotationalMotor {
          name "wheel3"
        }
      ]
      endPoint Solid {
        translation -0.05 0.06000000000000005 4.68944e-14
        rotation 0.9999999999999998 -9.589759999999996e-09 -9.589789999999996e-09 1.5707953071795862
        children [
          Shape {
            appearance PBRAppearance {
              baseColor 0 1 0
              roughness 1
              metalness 0
            }
            geometry Cylinder {
              height 0.02
              radius 0.04
            }
          }
        ]
        name "solid(2)"
        boundingObject USE Wheel_Geometry
        physics Physics {
        }
      }
    }
    HingeJoint {
      jointParameters HingeJointParameters {
        axis 0 1 0
        anchor -0.05 -0.06 1.22354e-07
      }
      device [
        RotationalMotor {
          name "wheel4"
        }
      ]
      endPoint Solid {
        translation -0.05 -0.06000000000000005 1.22354e-07
        rotation 0.9999999999999998 -9.589759999999996e-09 -9.589789999999996e-09 1.5707953071795862
        children [
          Shape {
            appearance PBRAppearance {
              baseColor 0 1 0
              roughness 1
              metalness 0
            }
            geometry Cylinder {
              height 0.02
              radius 0.04
            }
          }
        ]
        name "solid(3)"
        boundingObject USE Wheel_Geometry
        physics Physics {
        }
      }
    }
    DEF Body Shape {
      appearance PBRAppearance {
        baseColor 1 0 0
        roughness 1
        metalness 0
      }
      geometry DEF Body_Geometry Box {
        size 0.2 0.1 0.05
      }
    }
  ]
  boundingObject USE Body_Geometry
  physics Physics {
  }
  controller "four_wheeled_collision_avoidance"
}
